# Generated by Django 2.1.7 on 2019-04-01 09:48

from django.db import migrations, models


class Migration(migrations.Migration):

    initial = True

    dependencies = [
    ]

    operations = [
        migrations.CreateModel(
            name='ThirdPartyTransferError',
            fields=[
                ('id', models.BigAutoField(primary_key=True, serialize=False)),
                ('create_date', models.DateTimeField(blank=True, null=True)),
                ('last_update_date', models.DateTimeField(blank=True, null=True)),
                ('resource_id', models.CharField(blank=True, max_length=255, null=True)),
                ('resource_type', models.CharField(blank=True, max_length=255, null=True)),
                ('tenant_name', models.CharField(blank=True, max_length=128, null=True)),
                ('dealer_id', models.CharField(blank=True, max_length=64, null=True)),
                ('status', models.CharField(blank=True, max_length=255, null=True)),
                ('log_file_path', models.CharField(blank=True, max_length=512, null=True)),
                ('support_person', models.CharField(blank=True, max_length=512, null=True)),
                ('estimate_id', models.CharField(blank=True, max_length=255, null=True)),
                ('machine_id', models.CharField(blank=True, max_length=255, null=True)),
                ('service_advisor_id', models.CharField(blank=True, max_length=255, null=True)),
            ],
            options={
                'db_table': 'third_party_transfer_error',
                'managed': False,
            },
        ),
    ]
